<?xml version="1.0" ?>
<!-- =================================================================================== -->
<!-- |    This document was autogenerated by xacro from my_robot.urdf.xacro            | -->
<!-- |    EDITING THIS FILE BY HAND IS NOT RECOMMENDED                                 | -->
<!-- =================================================================================== -->
<robot name="dobot_magician">
  <!-- Baza robota -->
  <link name="base_link">
    <visual>
      <geometry>
        <box size="0.158 0.158 0.05"/>
      </geometry>
      <material name="grey"/>
    </visual>
  </link>
  <!-- Złącze 1: Obrót bazy -->
  <joint name="base_to_link1" type="revolute">
    <parent link="base_link"/>
    <child link="link1"/>
    <axis xyz="0 0 1"/>
    <limit effort="100" lower="-1.5708" upper="1.5708" velocity="1.0"/>
    <origin rpy="0 0 0" xyz="0 0 0.069"/>
  </joint>
  <!-- baza obrotowa  -->
  <link name="link1">
    <visual>
      <geometry>
        <cylinder length="0.088" radius="0.9"/>
      </geometry>
      <material name="blue"/>
    </visual>
  </link>
  <!-- Złącze 2:Ramie -->
  <joint name="link1_to_link2" type="revolute">
    <parent link="link1"/>
    <child link="link2"/>
    <axis xyz="1 0 0"/>
    <limit effort="100" lower="-1.5708" upper="1.5708" velocity="1.0"/>
    <origin rpy="0.78 0 0" xyz="0 0 0.044"/>
  </joint>
  <!-- ramie 1  -->
  <link name="link2">
    <visual>
      <origin rpy="0 0 0" xyz="0 0 0.0675"/>
      <geometry>
        <box size="0.03 0.03 0.135"/>
      </geometry>
      <material name="grey"/>
    </visual>
  </link>
  <!-- Złącze 3:Przedramie -->
  <joint name="link2_to_link3" type="revolute">
    <parent link="link2"/>
    <child link="link3"/>
    <axis xyz="1 0 0"/>
    <limit effort="100" lower="-1.5708" upper="1.5708" velocity="1.0"/>
    <origin rpy="0.78 0 0" xyz="0 0 0.135"/>
  </joint>
  <!-- przedramie  -->
  <link name="link3">
    <visual>
      <origin rpy="0 0 0" xyz="0 0 0.0675"/>
      <geometry>
        <box size="0.03 0.03 0.135"/>
      </geometry>
      <material name="grey"/>
    </visual>
  </link>
</robot>
